Workbook

Sheet Примеры
A1: Клеймы новых карточек — Корма и лакомства для собак и кошек (Ozon)
A2: 2026-07-31 (Day 0): кандидаты отобраны через фильтр Ozon «Новинки» — быстрый, но не полностью надёжный источник (Ozon продвигает не только объективно новые товары). Начиная с 2026-08-01: товары подтверждены объективно — сравнением ID с базой data/products_history.csv; их ID выше максимума, зафиксированного в предыдущем снимке той же категории. ДВА ОГРАНИЧЕНИЯ МЕТОДА: (1) Ложные срабатывания — «объективно новый ID» доказывает лишь то, что карточка на Ozon появилась впервые в поле зрения, не то, что сам товар впервые вышел на рынок. Из-за высокой доли 3P-продаж на Ozon один и тот же товар может получить новую отдельную карточку с новым ID при листинге ещё одним продавцом (например, 20-м по счёту) или при повторном листинге тем же продавцом — метод не всегда отличает это от действительно нового товара; распознанные вручную дубли (по фото/описанию) не учитываются повторно в аналитике, но не все подобные случаи гарантированно пойманы. (2) Пропуски — порог «ID выше максимума» предполагает монотонный рост ID во времени внутри подкатегории; если это нарушится (новая карточка получит ID ниже уже зафиксированного максимума), метод её не заметит вовсе — это ограничение работает в обратную сторону от первого. Колонки «Протеин» и «Ингредиенты-клеймы» — только то, что вынесено крупно на лицевую сторону упаковки (не полный состав мелким шрифтом). «Завод-изготовитель» — юрлицо и адрес производства с этикетки (не бренд и не импортёр/представитель), где это удалось разобрать по фото.
A4: Дата обнаружения | B4: Метод обнаружения | C4: Вид животного | D4: Тип продукции | E4: Бренд | F4: Название товара | G4: Протеин | H4: Ингредиенты-клеймы (лицевая сторона упаковки) | I4: Завод-изготовитель | J4: ID на Ozon | K4: Ссылка | L4: Фото упаковки | M4: Кол-во категорий клеймов | N4: Все клеймы (кратко)
A5: 2026-07-31 | B5: Сортировка «Новинки» (не подтверждено ID) | C5: Собаки | D5: Лакомства | E5: Triol | F5: Пончик жевательный с мясом утки | G5: Утка | H5: — | I5: Не найдено (в галерее Ozon только предметные фото товара, без этикетки состава) | J5: 5214515666 | K5: https://www.ozon.ru/product/zhevatelnyy-ponchik-s-myasom-utki-dlya-sobak-5214515666/ | M5: 3 | N5: 100% натурально; Dental (зубной налёт, дёсны); привлекает внимание
A6: 2026-07-31 | B6: Сортировка «Новинки» (не подтверждено ID) | C6: Собаки | D6: Сухой корм | E6: GRANDORF | F6: Fresh Adult MAXI, ягнёнок с бататом, 3 кг (беззерновой) | G6: Ягнёнок | H6: Батат; Omega-3/Omega-6; глюкозамин и хондроитин; живые пробиотики | I6: United Petfood Producer NV, Бельгия (завод PET 010); также указаны заводы группы во Франции и Нидерландах | J6: 5277005073 | K6: https://www.ozon.ru/product/suhoy-bezzernovoy-korm-grandorf-fresh-adult-maxi-dlya-sobak-krupnyh-porod-yagnenok-s-batatom-3-kg-v-5277005073/ | M6: 6 | N6: Holistic&Hypoallergenic; Gut Health/пробиотики; глюкозамин/хондроитин; Omega-3/6; Grain Free; мясо ягнёнка первым ингредиентом
A7: 2026-07-31 | B7: Сортировка «Новинки» (не подтверждено ID) | C7: Собаки | D7: Сухой корм | E7: AWARD | F7: Monoprotein, утка с яблоком и артишоком, 12 кг | G7: Утка | H7: Яблоко; артишок | I7: ООО «ПетЭксперт», Липецкая обл., Елецкий р-н, ОЭЗ ППТ «Липецк»; произведено для АО «Валта Пет Продактс» (Москва) | J7: 5276044539 | K7: https://www.ozon.ru/product/suhoy-korm-dlya-sobak-vseh-porod-award-monoprotein-iz-utki-s-dobavleniem-yablok-i-artishoka-12kg-5276044539/ | M7: 6 | N7: Premium Quality; Monoprotein; Hypo&Digestion; Low Grain; 100% BIO без ГМО; поддержка ЖКТ/иммунитета/кожи/мочевыдел.системы
A8: 2026-07-31 | B8: Сортировка «Новинки» (не подтверждено ID) | C8: Собаки | D8: Влажный корм | E8: GRANDORF | F8: Fresh, паштет из индейки, беззерновой, 6х200 г | G8: Индейка | H8: — | I8: Не проверено отдельно; вероятно United Petfood (тот же концерн, что и GRANDORF Fresh Adult MAXI) | J8: 5259070728 | K8: https://www.ozon.ru/product/vlazhnyy-korm-dlya-sobak-s-indeykoy-bezzernovoy-pashtet-grandorf-konservy-gipoallergennye-nabor-5259070728/ | M8: 4 | N8: Holistic&Hypoallergenic; 70% мяса; Monoprotein diet; Grain Free
A9: 2026-07-31 | B9: Сортировка «Новинки» (не подтверждено ID) | C9: Собаки | D9: Влажный корм | E9: CLAN VET | F9: Hepatic — профилактика болезней печени, 340 г | G9: Курица (субпродукты, по составу) | H9: — | I9: г. Елец, Липецкая обл., Россия (низкая уверенность в статусе — вероятно тот же промышленный кластер, что и ООО «ПетЭксперт» у AWARD) | J9: 5280647420 | K9: https://www.ozon.ru/product/vlazhnyy-dieticheskiy-korm-clan-vet-hepatic-dlya-sobak-profilaktika-bolezney-pecheni-340g-5280647420/ | M9: 1 | N9: VET / ветеринарная профилактическая диета; профилактика болезней печени
A10: 2026-07-31 | B10: Сортировка «Новинки» (не подтверждено ID) | C10: Собаки | D10: Лакомства | E10: Лопай лапой | F10: Лёгкое говяжье, сублимированное (freeze dried) | G10: Говядина | H10: — | I10: Не найдено (все 8 фото в галерее — маркетинговые инфографики без этикетки состава) | J10: 4685211777 | K10: https://www.ozon.ru/product/lakomstvo-sublimirovannoe-legkoe-govyazhe-naturalnye-freeze-dried-dog-treats-premialnyy-perekus-i-4685211777/ | M10: 4 | N10: 100% натуральный вкус; технология Freeze Dried; способствует очищению зубов; удобно для поощрения
A11: 2026-07-31 | B11: Сортировка «Новинки» (не подтверждено ID) | C11: Собаки | D11: Каши | E11: Альма | F11: Каша с говядиной, быстрого приготовления | G11: Говядина | H11: — | I11: ИП [фамилия неразборчива], г. Волгоград, Россия (адрес читается, имя предпринимателя — нет) | J11: 5110846419 | K11: https://www.ozon.ru/product/kasha-s-govyadinoy-alma-korm-dlya-sobak-naturalnyy-5110846419/ | M11: 2 | N11: Не требует варки; натуральное мясо в составе
A12: 2026-07-31 | B12: Сортировка «Новинки» (не подтверждено ID) | C12: Кошки | D12: Сухой корм | E12: Premier | F12: Lamb & Turkey Adult Large, гипоаллергенный, 400 г | G12: Ягнёнок + индейка | H12: — | I12: Не проверено отдельно; на лицевой стороне упаковки заявлено Made in Europe (страна не детализирована) | J12: 5277005334 | K12: https://www.ozon.ru/product/gipoallergennyy-suhoy-korm-dlya-vzroslyh-koshek-krupnyh-porod-premier-cat-lamb-turkey-adult-5277005334/ | M12: 5 | N12: Hypoallergenic; при чувствит. пищеварении; Low Grain/Gluten Free; без курицы/кукурузы/пшеницы/сои; мясо первым ингредиентом; Made in Europe
A13: 2026-07-31 | B13: Сортировка «Новинки» (не подтверждено ID) | C13: Кошки | D13: Сухой корм | E13: EDWIN | F13: Для кошек, склонных к аллергии, индейка, 8 кг | G13: Индейка | H13: — | I13: ООО «ПроРацион», Россия, 630110, г. Новосибирск, ул. Писемского, д. 24/1 | J13: 5243322000 | K13: https://www.ozon.ru/product/korm-suhoy-edwin-dlya-koshek-sklonnyh-k-allergii-indeyka-8-kg-5243322000/ | M13: 4 | N13: Premium Food for Cats; Hypoallergenic; оптимальное пищеварение; защита иммунитета; высокое содержание белка
A14: 2026-07-31 | B14: Сортировка «Новинки» (не подтверждено ID) | C14: Кошки | D14: Влажный корм | E14: GRANDORF | F14: Fresh, филе тунца с лососем в желе, 6х70 г | G14: Тунец + лосось | H14: — | I14: Таиланд (страна заявлена на лицевой стороне упаковки, конкретное юрлицо не проверялось) | J14: 5248949561 | K14: https://www.ozon.ru/product/grandorf-fresh-vlazhnyy-korm-dlya-koshek-tunets-losos-6sht-h-70g-5248949561/ | M14: 3 | N14: Holistic Nutrition; 60% мяса; филе тунца/лосося; Сделано в Таиланде
A15: 2026-07-31 | B15: Сортировка «Новинки» (не подтверждено ID) | C15: Кошки | D15: Лакомства | E15: Titbit | F15: Трава для кошек (для проращивания), 40 г х 12 | G15: —(не мясной продукт, трава) | H15: Трава (овёс); витамины и фолиевая кислота (восполняет запас) | I15: Не найдено (только 2 фото в галерее, без этикетки) | J15: 4098300679 | K15: https://www.ozon.ru/product/titbit-lakomstva-dlya-koshek-oves-dlya-prorashchivaniya-40-gr-12-up-4098300679/ | M15: 2 | N15: 100% натурально; немодифицированные семена; способствует пищеварению/выведению шерсти
A16: 2026-08-01 | B16: Подтверждено: ID выше макс. известного на 2026-07-31 | C16: Собаки | D16: Сухой корм | E16: Gosbi | F16: PROFESSIONAL GF Puppy, лосось с ягнёнком, 18 кг (беззерновой) | G16: Лосось + ягнёнок | H16: — | I16: Не проверено отдельно; Gosbi — испанский бренд (Средиземноморское позиционирование на упаковке) | J16: 5293611532 | K16: https://www.ozon.ru/product/gosbi-professional-gf-puppy-losos-yagnenok-18-kg-suhoy-bezzernovoy-korm-dlya-shchenkov-vseh-porod-5293611532/ | M16: 3 | N16: Grain Free; Mediterranean gourmet; Professional (премиум-позиционирование)
... A114: 2026-08-12 | B114: Подтверждено: ID выше макс. известного на 2026-08-04 | C114: Собаки | D114: Сухой корм | E114: Farmina N&D | F114: Ancestral Grain, ягнёнок, полба, овёс и черника, для взрослых собак, 12 кг | G114: Ягнёнок | H114: Полба; Овёс; Черника | I114: Farmina Pet Foods, Италия | J114: 5424780417 | K114: https://www.ozon.ru/product/5424780417/ | M114: 2 | N114: Ancestral Grain (древние злаки, низкозерновая рецептура); Nutrition System for Carnivores; Italian formula

Sheet Клеймы
A1: ID товара | B1: Название товара | C1: Вид животного | D1: Тип продукции | E1: Код категории | F1: Категория клейма | G1: Формулировки на упаковке
A2: 5214515666 | B2: Пончик жевательный с мясом утки | C2: Собаки | D2: Лакомства | E2: NAT | F2: Натуральность состава | G2: 100% натурально
A3: 5214515666 | B3: Пончик жевательный с мясом утки | C3: Собаки | D3: Лакомства | E3: DENT | F3: Стоматологическая польза | G3: Dental; снимает зубной налёт; массирует дёсна
A4: 5214515666 | B4: Пончик жевательный с мясом утки | C4: Собаки | D4: Лакомства | E4: TASTE | F4: Вкусовая привлекательность / поведение | G4: Привлекают внимание собаки на долгое время
A5: 5277005073 | B5: GRANDORF Fresh Adult MAXI | C5: Собаки | D5: Сухой корм | E5: HYPO | F5: Гипоаллергенность / чувствит. пищеварение | G5: Hypoallergenic; при чувствительном пищеварении
A6: 5277005073 | B6: GRANDORF Fresh Adult MAXI | C6: Собаки | D6: Сухой корм | E6: HOLISTIC | F6: Холистик-позиционирование | G6: Holistic
A7: 5277005073 | B7: GRANDORF Fresh Adult MAXI | C7: Собаки | D7: Сухой корм | E7: FUNC | F7: Функциональная польза для здоровья | G7: Gut Health — Live Probiotics; Glucosamine and Chondroitin; Omega-3, Omega-6 Fatty Acids
A8: 5277005073 | B8: GRANDORF Fresh Adult MAXI | C8: Собаки | D8: Сухой корм | E8: NAT | F8: Натуральность состава | G8: 100% Natural Dog Food
A9: 5277005073 | B9: GRANDORF Fresh Adult MAXI | C9: Собаки | D9: Сухой корм | E9: GRAIN | F9: Беззерновой / монобелковый состав | G9: Grain Free; No: Grains, Chicken, By-products
A10: 5277005073 | B10: GRANDORF Fresh Adult MAXI | C10: Собаки | D10: Сухой корм | E10: MEAT | F10: Происхождение и качество мяса | G10: Fresh Lamb is the first ingredient
A11: 5276044539 | B11: AWARD Monoprotein (утка) | C11: Собаки | D11: Сухой корм | E11: HYPO | F11: Гипоаллергенность / чувствит. пищеварение | G11: Hypo & Digestion — при пищевой аллергии и непереносимости
A12: 5276044539 | B12: AWARD Monoprotein (утка) | C12: Собаки | D12: Сухой корм | E12: FUNC | F12: Функциональная польза для здоровья | G12: Поддержка пищеварения и иммунитета; поддержка мочевыделяющей системы; здоровая кожа и блестящая шерсть; крепкий иммунитет каждый день
... A266: 5424780417 | B266: Farmina N&D Ancestral Grain ягнёнок+черника (собаки) | C266: Собаки | D266: Сухой корм | E266: PREMIUM | F266: Премиальное позиционирование | G266: Italian formula

Sheet Клеймы-справочник
A1: Код | B1: Категория клейма | C1: Описание | D1: Типичные формулировки
A2: HYPO | B2: Гипоаллергенность / чувствит. пищеварение | C2: Заявления об отсутствии типичных аллергенов, подходит при непереносимости, для чувствительного ЖКТ | D2: Hypoallergenic; при чувствительном пищеварении; Hypo & Digestion; без курицы/кукурузы/пшеницы/сои
A3: FUNC | B3: Функциональная польза для здоровья | C3: Конкретные функциональные преимущества сверх базового питания: иммунитет, суставы, кожа/шерсть, мочевыдел. система, ЖКТ | D3: Поддержка иммунитета; Glucosamine & Chondroitin; Omega-3/6; Gut Health; здоровая кожа и шерсть
A4: DENT | B4: Стоматологическая польза | C4: Уход за зубами и дёснами | D4: Dental; снимает зубной налёт; массирует дёсна; способствует очищению зубов
A5: VET | B5: Ветеринарная / лечебная диета | C5: Диета для профилактики или коррекции конкретных заболеваний, ветеринарное позиционирование бренда | D5: VET; профилактика болезней печени/почек/ЖКТ; лечебный корм
A6: NAT | B6: Натуральность состава | C6: Отсутствие искусственных добавок, ГМО, «чистая» этикетка (без отдельного заявления Holistic — см. код HOLISTIC) | D6: 100% натурально; без ГМО, красителей и ароматизаторов; 100% BIO; без глицерина
A7: HOLISTIC | B7: Холистик-позиционирование | C7: Отдельный маркетинговый термин «holistic» — философия рецептуры, часто идёт рядом с NAT/HYPO, но заявляется как отдельный статус, а не просто «натурально» | D7: Holistic; Holistic Nutrition; Holistic & Hypoallergenic
A8: GRAIN | B8: Беззерновой / монобелковый состав | C8: Особый тип рецептуры по составу углеводов/белка | D8: Grain Free; Monoprotein; Low Grain; Gluten Free
A9: MEAT | B9: Происхождение и качество мяса | C9: Доля мяса, место мяса в составе, вид/качество ингредиента | D9: Мясо первым ингредиентом; 60-70% мяса; филе тунца/лосося; высокое содержание белка
A10: TECH | B10: Особая технология производства | C10: Способ обработки продукта, отличный от стандартного | D10: Freeze Dried; сублимированное; холодное прессование
A11: CONV | B11: Удобство использования | C11: Практичность для владельца при приготовлении/хранении | D11: Не требует варки; готовый рацион; быстрого приготовления
A12: ORIGIN | B12: Страна / регион производства | C12: Указание конкретной страны, региона или национальной принадлежности бренда (без оценки премиальности самой по себе) | D12: Made in Europe; Сделано в Таиланде; Сделано на Кубани; Произведено на Алтае; Mediterranean gourmet; «Корма из России»
... A14: TASTE | B14: Вкусовая привлекательность / поведенческая польза | C14: Ориентация на удовольствие питомца или поведенческий эффект (игра, дрессировка, вывод шерсти) | D14: Любимое лакомство; для дрессировки; привлекает внимание; трава для кошек

Sheet Протеин-Ингредиенты-Завод
A1: ID товара | B1: Название товара | C1: Тип тега | D1: Значение
A2: 5214515666 | B2: Пончик жевательный с мясом утки | C2: Протеин | D2: Утка
A3: 5277005073 | B3: Fresh Adult MAXI, ягнёнок с бататом, 3 кг (беззерновой) | C3: Протеин | D3: Ягнёнок
A4: 5276044539 | B4: Monoprotein, утка с яблоком и артишоком, 12 кг | C4: Протеин | D4: Утка
A5: 5259070728 | B5: Fresh, паштет из индейки, беззерновой, 6х200 г | C5: Протеин | D5: Индейка
A6: 5280647420 | B6: Hepatic — профилактика болезней печени, 340 г | C6: Протеин | D6: Курица
A7: 4685211777 | B7: Лёгкое говяжье, сублимированное (freeze dried) | C7: Протеин | D7: Говядина
A8: 5110846419 | B8: Каша с говядиной, быстрого приготовления | C8: Протеин | D8: Говядина
A9: 5277005334 | B9: Lamb & Turkey Adult Large, гипоаллергенный, 400 г | C9: Протеин | D9: Ягнёнок
A10: 5277005334 | B10: Lamb & Turkey Adult Large, гипоаллергенный, 400 г | C10: Протеин | D10: Индейка
A11: 5243322000 | B11: Для кошек, склонных к аллергии, индейка, 8 кг | C11: Протеин | D11: Индейка
A12: 5248949561 | B12: Fresh, филе тунца с лососем в желе, 6х70 г | C12: Протеин | D12: Тунец
... A330: 5424780417 | B330: Ancestral Grain, ягнёнок, полба, овёс и черника, для взрослых собак, 12 кг | C330: Производитель | D330: Италия

Sheet Аналитика
A1: Аналитика: популярность направлений клеймов среди новых карточек
A2: Выборка: 110 карточек (собаки+кошки, корма и лакомства) за 5 снимков — 11 отобраны 2026-07-31 через сортировку «Новинки» (не подтверждено ID), 13 добавлены 2026-08-01, 27 добавлены 2026-08-03, 17 добавлены 2026-08-04 и 42 добавлены 2026-08-12 (включая 11, найденных доп. аудитом ?sorting=new — пропущены при первом проходе, см. «Ограничения метода») — все 99 подтверждены сравнением ID с базой (объективно новые). Полностью разобраны (клеймы+протеин+ингредиенты+завод) все объективно новые карточки, кроме 15 дублей по весу/размеру упаковки той же рецептуры или повторного листинга того же товара (не считаются повторно ни по одному признаку) и 1 сопутствующего товара (трава для кошек — набор для выращивания, не корм/лакомство).
A4: Код | B4: Категория клейма | C4: Товаров с этой категорией | D4: Доля от выборки
A5: HYPO | B5: Гипоаллергенность / чувствит. пищеварение | C5: =COUNTIF(Клеймы!E:E,A5) | D5: =C5/110
A6: FUNC | B6: Функциональная польза для здоровья | C6: =COUNTIF(Клеймы!E:E,A6) | D6: =C6/110
A7: DENT | B7: Стоматологическая польза | C7: =COUNTIF(Клеймы!E:E,A7) | D7: =C7/110
A8: VET | B8: Ветеринарная / лечебная диета | C8: =COUNTIF(Клеймы!E:E,A8) | D8: =C8/110
A9: NAT | B9: Натуральность состава | C9: =COUNTIF(Клеймы!E:E,A9) | D9: =C9/110
A10: HOLISTIC | B10: Холистик-позиционирование | C10: =COUNTIF(Клеймы!E:E,A10) | D10: =C10/110
A11: GRAIN | B11: Беззерновой / монобелковый состав | C11: =COUNTIF(Клеймы!E:E,A11) | D11: =C11/110
A12: MEAT | B12: Происхождение и качество мяса | C12: =COUNTIF(Клеймы!E:E,A12) | D12: =C12/110
A13: TECH | B13: Особая технология производства | C13: =COUNTIF(Клеймы!E:E,A13) | D13: =C13/110
A14: CONV | B14: Удобство использования | C14: =COUNTIF(Клеймы!E:E,A14) | D14: =C14/110
A15: ORIGIN | B15: Страна / регион производства | C15: =COUNTIF(Клеймы!E:E,A15) | D15: =C15/110
A16: PREMIUM | B16: Премиальное позиционирование | C16: =COUNTIF(Клеймы!E:E,A16) | D16: =C16/110
A17: TASTE | B17: Вкусовая привлекательность / поведенческая польза | C17: =COUNTIF(Клеймы!E:E,A17) | D17: =C17/110
A18: Итого товаров в выборке: | C18: 110
A21: Протеин — популярность по ВСЕМ SKU новых линеек (не по одному товару на линейку), 110 SKU всего
A23: Значение | B23: Товаров | C23: Доля
A24: Баранина | B24: =COUNTIFS('Протеин-Ингредиенты-Завод'!C:C,"Протеин",'Протеин-Ингредиенты-Завод'!D:D,A24) | C24: =B24/94
A25: Белая рыба | B25: =COUNTIFS('Протеин-Ингредиенты-Завод'!C:C,"Протеин",'Протеин-Ингредиенты-Завод'!D:D,A25) | C25: =B25/94
A26: Говядина | B26: =COUNTIFS('Протеин-Ингредиенты-Завод'!C:C,"Протеин",'Протеин-Ингредиенты-Завод'!D:D,A26) | C26: =B26/94
A27: Гребешок | B27: =COUNTIFS('Протеин-Ингредиенты-Завод'!C:C,"Протеин",'Протеин-Ингредиенты-Завод'!D:D,A27) | C27: =B27/94
A28: Индейка | B28: =COUNTIFS('Протеин-Ингредиенты-Завод'!C:C,"Протеин",'Протеин-Ингредиенты-Завод'!D:D,A28) | C28: =B28/94
A29: Кабан | B29: =COUNTIFS('Протеин-Ингредиенты-Завод'!C:C,"Протеин",'Протеин-Ингредиенты-Завод'!D:D,A29) | C29: =B29/94
A30: Калтык и язык | B30: =COUNTIFS('Протеин-Ингредиенты-Завод'!C:C,"Протеин",'Протеин-Ингредиенты-Завод'!D:D,A30) | C30: =B30/94
A31: Краб | B31: =COUNTIFS('Протеин-Ингредиенты-Завод'!C:C,"Протеин",'Протеин-Ингредиенты-Завод'!D:D,A31) | C31: =B31/94
A32: Креветки | B32: =COUNTIFS('Протеин-Ингредиенты-Завод'!C:C,"Протеин",'Протеин-Ингредиенты-Завод'!D:D,A32) | C32: =B32/94
A33: Кролик | B33: =COUNTIFS('Протеин-Ингредиенты-Завод'!C:C,"Протеин",'Протеин-Ингредиенты-Завод'!D:D,A33) | C33: =B33/94
A34: Курица | B34: =COUNTIFS('Протеин-Ингредиенты-Завод'!C:C,"Протеин",'Протеин-Ингредиенты-Завод'!D:D,A34) | C34: =B34/94
A35: Лосось | B35: =COUNTIFS('Протеин-Ингредиенты-Завод'!C:C,"Протеин",'Протеин-Ингредиенты-Завод'!D:D,A35) | C35: =B35/94
... A46: Ягнёнок | B46: =COUNTIFS('Протеин-Ингредиенты-Завод'!C:C,"Протеин",'Протеин-Ингредиенты-Завод'!D:D,A46) | C46: =B46/94
A47: База 100% = 94 (94 SKU, где протеин назван на лицевой стороне упаковки, из 110 SKU всего (все объективно новые SKU за 5 снимков, 2026-07-31 — 2026-08-12))
A50: Ингредиенты-клеймы (лицевая сторона упаковки) — популярность среди новых карточек
A52: Значение | B52: Товаров | C52: Доля
A53: Ca/P | B53: =COUNTIFS('Протеин-Ингредиенты-Завод'!C:C,"Ингредиент-клеймо",'Протеин-Ингредиенты-Завод'!D:D,A53) | C53: =B53/110
A54: Артишок | B54: =COUNTIFS('Протеин-Ингредиенты-Завод'!C:C,"Ингредиент-клеймо",'Протеин-Ингредиенты-Завод'!D:D,A54) | C54: =B54/110
A55: Батат | B55: =COUNTIFS('Протеин-Ингредиенты-Завод'!C:C,"Ингредиент-клеймо",'Протеин-Ингредиенты-Завод'!D:D,A55) | C55: =B55/110
A56: Болгарский перец | B56: =COUNTIFS('Протеин-Ингредиенты-Завод'!C:C,"Ингредиент-клеймо",'Протеин-Ингредиенты-Завод'!D:D,A56) | C56: =B56/110
A57: Брокколи | B57: =COUNTIFS('Протеин-Ингредиенты-Завод'!C:C,"Ингредиент-клеймо",'Протеин-Ингредиенты-Завод'!D:D,A57) | C57: =B57/110
...
